Workbook
Name Excel_BuiltIn_Print_Area_1: 0
Name Excel_BuiltIn_Print_Area_1_1: 0
Name Excel_BuiltIn_Print_Area_10: 0
Name Excel_BuiltIn_Print_Area_2: 0
Name Excel_BuiltIn_Print_Area_2_1: 0
Name Excel_BuiltIn_Print_Area_3: 0
Name Excel_BuiltIn_Print_Area_3_1: 0
Name Excel_BuiltIn_Print_Area_4: 0
Name Excel_BuiltIn_Print_Area_5: 0
Name Excel_BuiltIn_Print_Area_6: 0
Name Excel_BuiltIn_Print_Area_7: 0
Name Excel_BuiltIn_Print_Area_8: 0
Name Excel_BuiltIn_Print_Area_9: 0

Sheet 116
A2: Machine Brand | B2: EGT | C2: A
B3: MEGA VISION
A4: 1 Credit = $ | B4: 1
A6: Machine Number | B6: 116
A7: GAME | B7: MULTI GAMES
A8: TOTAL BET (COIN IN) | B8: 9854928
A9: TOTAL CASHABLE PLAYED | B9: =B8 -> 9854928
A10: TOTAL PROMOTIONAL PLAYED | B10: 0 | D10: Ll
A11: TOTAL NON-CASHABLE PLAYED | B11: 0
A13: TOTAL WON | B13: 9520465.4
A14: TOTAL WINNINGS TO CREDIT | B14: 9382180.8
A15: WINNINGS FROM PAYTABLE (COIN OUT) | B15: =B14 -> 9382180.8
A16: WINNINGS FROM PROGRESSIVES | B16: 0
A17: WINNINGS FROM EXTERNAL BONUSES | B17: 0
A18: TOTAL WINNINGS PAID BY ATTENDANT | B18: 138284.6
A19: Attendant Paid Paytable Winnings | B19: =+B18 -> 138284.6
A20: Attedant Paid Progressives | B20: 0
A21: Attendant Paid External Bonuses | B21: 0
B23: 0
A24: Machine Hold % | B24: 0.034
A25: Machine Yield % | B25: 0.966
A26: Weighted average TRTP % | B26: 0.9573
A28: TOTAL IN | B28: 2490709.9
A29: Physical Coin In | B29: 0
A30: Bill In | B30: 1482958
A31: Cashless in | B31: 1007751.9
A32: Cashable Electronic in | B32: =+B31 -> 1007751.9
A33: KEYED IN | B33: .
A34: Promotional Electronic In | B34: 0
A35: Non cashable electronic In | B35: 0
A36: Voucher In | B36: 0
A37: Cashable voucher In | B37: 0
A38: Promotional voucher in | B38: 0
A39: Non-cashable Voucher In | B39: 0
A41: TOTAL OUT | B41: 2156247.3
A42: Physical Coin Out | B42: 0
A43: Total Winnings Paid By Attendant | B43: 138284.6
A44: Cancelled Credits Paid by Attendant | B44: 303.44
A45: VOUCHER OUT | B45: 0
A46: Cashable Voucher Out | B46: 0
...

Sheet 96
I1: AMES WON
A2: Machine Brand | B2: ATRONIC
A4: 1 Credit = $ | B4: 1
A6: Machine Number | B6: 96
A7: GAME | B7: OUTSTANDING ORANGE DELUXE
A8: True In | B8: 225080.75
A9: Pysical Coin In | B9: 0
A10: Bills in | B10: 87795
A11: Total voucher In | B11: 0
A12: Total Cashless Transactions In | B12: 137285.75
A13: Money Wagered | B13: 634558.74
A14: Money Won (incl Bonus Jackpot) | B14: 5765873.5
A15: Money Won (incl Bonus JP Bonus) | B15: 589879.47 | C15: 94926.51
A16: Money Won (incl Bonus JP Bonus, Jackpot) | B16: =B15 -> 589879.47 | C16: 394248.87
A17: Total Bonus In | B17: 0 | C17: 35488
A18: True Out | B18: 180401.48
A19: Physical Coin Out | B19: 0
A20: Total voucher Out | B20: 0
A21: Total Cashless Transactions Out | B21: =B18 -> 180401.48
A22: Handpay | B22: 0
A23: Handpay (Incl Jackpot) | B23: 0
A24: Jackpot | B24: 0
A25: Jackpot (Incl Progressive JP, Bonus) | B25: 0
A26: Net Win(Incl Progressive JP) | B26: 44679.27
A27: Net Win (Incl Progressive JP, Bonus) | B27: =B26 -> 44679.27
A28: Total Drop | B28: 87795
A29: Current Payout %(Incl Progressive JP) | B29: 0.9295
A30: Current Payout % (Incl Progressive JP, Bonus) | B30: =+B29 -> 0.9295

Sheet 43
A2: Machine Brand | B2: EGT | C2: A
B3: MEGA VISION
A4: 1 Credit = $ | B4: 1
A6: Machine Number | B6: 43
A7: GAME | B7: MULTI GAMES
A8: TOTAL BET (COIN IN) | B8: 17267146
A9: TOTAL CASHABLE PLAYED | B9: =B8 -> 17267146
A10: TOTAL PROMOTIONALPLAYED | B10: 0
A11: TOTAL NONCASHABLE PLAYED | B11: 0
A13: TOTAL WON | B13: 16402434
A14: TOTAL WINNINGS TO CREDIT | B14: 16273584
A15: WINNINGS PAYTABLE(COIN OUT) | B15: =B14 -> 16273584
A16: WINNINGS FROM PROGRESSIVES | B16: 0
A17: WINNINGS FROM EXTERNAL BONUSES | B17: 0
A18: TOTAL WINNINGS PAID BY ATTENDANT | B18: 128850
A19: Attendant Paid Paytable | B19: =+B18 -> 128850
A20: Attedant Paid Progressives | B20: 0
A21: Attendant Paid External Bonuses | B21: 0
A24: TOTAL IN | B24: 4721454.7 | E24: =B24=B26+B27 -> TRUE
A25: Physical Coin In | B25: 0 | H25: 2903100
A26: Bill In | B26: 3055780 | H26: =+H25-B26 -> -152680
A27: Cashless in | B27: 1665674.6
A28: Cashable Electronic in | B28: =B27 -> 1665674.6
A29: KEYED IN | B29: 0
A30: Promotional Electronic In | B30: 0
A31: Non-cashable electronic In | B31: 0
A32: VOUCHER IN | B32: 0
A33: Cashable Voucher in | B33: 0
A34: promotional Voucher in | B34: 0
A35: Non-cashable Voucher in | B35: 0
A37: TOTAL OUT | B37: 3856741.8
A38: Physical Coin Out | B38: 0
A39: Total Winnings Paid By Attendant | B39: 128850
A40: Cancelled Credits Paid by Attendant | B40: 2188.06
A41: VOUCHER OUT | B41: 0
... A43: non-cashable Voucher Out | B43: 0
A44: CASHLESS OUT | B44: 3725703.8 | J44: 33
A45: Cashable Electronic Out | B45: =B44 -> 3725703.8
A46: Promotional Electronic Out | B46: 0
A47: Non-cashable Electronic Out | B47: 0
...

Sheet 111
A2: Machine Brand | B2: EGT | C2: A
B3: MEGA VISION
A4: 1 Credit = $ | B4: 1
A6: Machine Number | B6: 111
A7: GAME | B7: MULTI GAMES
A8: TOTAL BET (COIN IN) | B8: 7996478.6
A9: TOTAL CASHABLE PLAYED | B9: =B8 -> 7996478.6
A10: TOTAL PROMOTIONAL PLAYED | B10: 0
A11: TOTAL NON-CASHABLE PLAYED | B11: 0
A13: TOTAL WON | B13: 7586630
A14: TOTAL WINNINGS TO CREDIT | B14: 7491305.5
A15: WINNINGS FROM PAYTABLE (COIN OUT) | B15: =B14 -> 7491305.5
A16: WINNINGS FROM PROGRESSIVES | B16: 0
A17: WINNINGS FROM EXTERNAL BONUSES | B17: 0
A18: TOTAL WINNINGS PAID BY ATTENDANT | B18: 95324.5
A19: Attendant Paid Paytable Winnings | B19: =+B18 -> 95324.5
A20: Attedant Paid Progressives | B20: 0
A21: Attendant Paid External Bonuses | B21: 0
B23: 0
A24: Machine Hold % | B24: 0.0533
A25: Machine Yield % | B25: 0.9467
A26: Weighted average TRTP % | B26: 0.9568
A28: TOTAL IN | B28: 1833030.7
A29: Physical Coin In | B29: 0
A30: Bill In | B30: 1095813
A31: Cashless in | B31: 737217.66
A32: Cashable Electronic in | B32: =+B31 -> 737217.66
A33: KEYED IN | B33: 0
A34: Promotional Electronic In | B34: 0
A35: Non cashable electronic In | B35: 0
A36: Voucher In | B36: 0
A37: Cashable voucher In | B37: 0
A38: Promotional voucher in | B38: 0
A39: Non-cashable Voucher In | B39: 0
A41: TOTAL OUT | B41: 1423182.1
A42: Physical Coin Out | B42: 0
A43: Total Winnings Paid By Attendant | B43: 95324.5
A44: Cancelled Credits Paid by Attendant | B44: 326.72
A45: VOUCHER OUT | B45: 0
... A48: CASHLESS OUT | B48: 1327530.8
...

Sheet 92
I1: AMES WON
A2: Machine Brand | B2: ATRONIC
A4: 1 Credit = $ | B4: 1
A6: Machine Number | B6: 92
A7: GAME | B7: LEGENDARY CLASSICS DELUXE
A8: True In | B8: 238365.69
A9: Pysical Coin In | B9: 0
A10: Bills in | B10: 127211
A11: Total voucher In | B11: 0
A12: Total Cashless Transactions In | B12: 111154.69
A13: Money Wagered | B13: 975486.61
A14: Money Won (incl Bonus Jackpot) | B14: 919053.12
A15: Money Won (incl Bonus JP Bonus) | B15: 923643.75
A16: Money Won (incl Bonus JP Bonus, Jackpot) | B16: =B15 -> 923643.75
A17: Total Bonus In | B17: 0
A18: True Out | B18: 186522.83
A19: Physical Coin Out | B19: 0
A20: Total voucher Out | B20: 0
A21: Total Cashless Transactions Out | B21: =B18 -> 186522.83
A22: Handpay | B22: 0
A23: Handpay (Incl Jackpot) | B23: 0 | E23: =+B23-B41 -> 0
A24: Jackpot | B24: 0
A25: Jackpot (Incl Progressive JP, Bonus) | B25: 0
A26: Net Win(Incl Progressive JP) | B26: 51842.86
A27: Net Win (Incl Progressive JP, Bonus) | B27: =+B26 -> 51842.86
A28: Total Drop | B28: 127211
A29: Current Payout %(Incl Progressive JP) | B29: 0.9468
A30: Current Payout % (Incl Progressive JP, Bonus) | B30: =B29 -> 0.9468

Sheet 91
I1: AMES WON
A2: Machine Brand | B2: ATRONIC
A4: 1 Credit = $ | B4: 1
A6: Machine Number | B6: 91
A7: GAME | B7: MAGNIFICENT MAGENTA DELUXE
A8: True In | B8: 306561.96
A9: Pysical Coin In | B9: 0
A10: Bills in | B10: 148748
A11: Total voucher In | B11: 0
A12: Total Cashless Transactions In | B12: 157813.96 | C12: 47
A13: Money Wagered | B13: 1058066.5
A14: Money Won (incl Bonus Jackpot) | B14: 1004415.7
A15: Money Won (incl Bonus JP Bonus) | B15: 1009019.3
A16: Money Won (incl Bonus JP Bonus, Jackpot) | B16: =B15 -> 1009019.3
A17: Total Bonus In | B17: 0
A18: True Out | B18: 257514.77
A19: Physical Coin Out | B19: 0
A20: Total voucher Out | B20: 0
A21: Total Cashless Transactions Out | B21: =B18 -> 257514.77
A22: Handpay | B22: 0
A23: Handpay (Incl Jackpot) | B23: 0 | E23: =+B23-B41 -> 0
A24: Jackpot | B24: 0
A25: Jackpot (Incl Progressive JP, Bonus) | B25: 0
A26: Net Win(Incl Progressive JP) | B26: 49047.19
A27: Net Win (Incl Progressive JP, Bonus) | B27: =B26 -> 49047.19
A28: Total Drop | B28: 148748
A29: Current Payout %(Incl Progressive JP) | B29: 0.9536
A30: Current Payout % (Incl Progressive JP, Bonus) | B30: =B29 -> 0.9536

Sheet 40
A2: Machine Brand | B2: EGT | C2: A
B3: MEGA VISION
A4: 1 Credit = $ | B4: 1 | I4: 2
A6: Machine Number | B6: 40
A7: GAME | B7: MULTI GAMES
A8: TOTAL BET (COIN IN) | B8: 17484784
A9: TOTAL CASHABLE PLAYED | B9: =+B8 -> 17484784
A10: TOTAL PROMOTIONALPLAYED | B10: 0
A11: TOTAL NONCASHABLE PLAYED | B11: 0
A13: TOTAL WON | B13: 16717389
A14: TOTAL WINNINGS TO CREDIT | B14: 16656201
A15: WINNINGS PAYTABLE(COIN OUT) | B15: =B14 -> 16656201
A16: WINNINGS FROM PROGRESSIVES | B16: 0
A17: WINNINGS FROM EXTERNAL BONUSES | B17: 0
A18: TOTAL WINNINGS PAID BY ATTENDANT | B18: 61188 | G18: 2
A19: Attendant Paid Paytable | B19: =B18 -> 61188
A20: Attedant Paid Progressives | B20: 0
A21: Attendant Paid External Bonuses | B21: 0
A24: TOTAL IN | B24: 4495301.8
A25: Physical Coin In | B25: 0 | E25: on
A26: Bill In | B26: 3116190 | E26: =B24=B26+B27 -> TRUE
A27: Cashless in | B27: 1379111.9
A28: Cashable Electronic in | B28: =B27 -> 1379111.9
A29: KEYED IN | B29: 0
A30: Promotional Electronic In | B30: 0
A31: Non-cashable Electronic In | B31: 0
B32: 0
A33: VOUCHER IN
A34: Cashable Voucher in | B34: 0
A35: promotional Voucher in | B35: 0
A36: Non-cashable Voucher in | B36: 0
A38: TOTAL OUT | B38: 3727907.2
A39: Physical Coin Out | B39: 0
A40: Total Winnings Paid By Attendant | B40: 61188
A41: cancelled credits paid by attendant | B41: 2880.64
A42: VOUCHER OUT | B42: 0
A43: Cashable Voucher Out | B43: 0
A44: non-cashable Voucher Out | B44: 0
A45: CASHLESS OUT | B45: 3663838.6
A46: Cashable Electronic Out | B46: =+B45 -> 3663838.6
...

Sheet 117
A2: Machine Brand | B2: EGT | C2: A
B3: MEGA VISION
A4: 1 Credit = $ | B4: 1
A6: Machine Number | B6: 117
A7: GAME | B7: MULTI GAMES
A8: TOTAL BET (COIN IN) | B8: 8023840.4
A9: TOTAL CASHABLE PLAYED | B9: =B8 -> 8023840.4
A10: TOTAL PROMOTIONAL PLAYED | B10: 0
A11: TOTAL NON-CASHABLE PLAYED | B11: 0
A13: TOTAL WON | B13: 7709411.8
A14: TOTAL WINNINGS TO CREDIT | B14: 7607383.8
A15: WINNINGS FROM PAYTABLE (COIN OUT) | B15: =B14 -> 7607383.8
A16: WINNINGS FROM PROGRESSIVES | B16: 0
A17: WINNINGS FROM EXTERNAL BONUSES | B17: 0
A18: TOTAL WINNINGS PAID BY ATTENDANT | B18: 102028
A19: Attendant Paid Paytable Winnings | B19: =+B18 -> 102028
A20: Attedant Paid Progressives | B20: 0
A21: Attendant Paid External Bonuses | B21: 0
B23: 0
A24: Machine Hold % | B24: 0.0392
A25: Machine Yield % | B25: 0.9608
A26: Weighted average TRTP % | B26: 0.9569
B27: 95.56
A28: TOTAL IN | B28: 1939246.1
A29: Physical Coin In | B29: 0
A30: Bill In | B30: 1118490
A31: Cashless in | B31: 820756.05
A32: Cashable Electronic in | B32: =B31 -> 820756.05
A33: KEYED IN | B33: 0
A34: Promotional Electronic In | B34: 0
A35: Non cashable electronic In | B35: 0
A36: Voucher In | B36: 0
A37: Cashable voucher In | B37: 0
A38: Promotional voucher in | B38: 0
A39: Non-cashable Voucher In | B39: 0
A41: TOTAL OUT | B41: 1624817.4
A42: Physical Coin Out | B42: 0
A43: Total Winnings Paid By Attendant | B43: 102028
A44: Cancelled Credits Paid by Attendant | B44: 1090.37
A45: VOUCHER OUT | B45: 0
...

Sheet 41
A2: Machine Brand | B2: EGT | C2: A
B3: MEGA VISION
A4: 1 Credit = $ | B4: 1
A6: Machine Number | B6: 41
A7: GAME | B7: MULTI GAMES
A8: TOTAL BET (COIN IN) | B8: 17527423
A9: TOTAL CASHABLE PLAYED | B9: =B8 -> 17527423
A10: TOTAL PROMOTIONALPLAYED | B10: 0
A11: TOTAL NONCASHABLE PLAYED | B11: 0
A13: TOTAL WON | B13: 16663023
A14: TOTAL WINNINGS TO CREDIT | B14: 16630061
A15: WINNINGS PAYTABLE(COIN OUT) | B15: =+B14 -> 16630061
A16: WINNINGS FROM PROGRESSIVES | B16: 0
A17: WINNINGS FROM EXTERNAL BONUSES | B17: 0
A18: TOTAL WINNINGS PAID BY ATTENDANT | B18: 32962
A19: Attendant Paid Paytable | B19: =B18 -> 32962
A20: Attedant Paid Progressives | B20: 0
A21: Attendant Paid External Bonuses | B21: 0
B22: 0
A23: TOTAL IN | B23: 4485292.1
A24: Physical Coin In | B24: 0 | E24: =B23=B25+B26 -> TRUE
A25: Bill In | B25: 3199850
A26: Cashless in | B26: 1285442.1
A27: Cashable Electronic in | B27: =B26 -> 1285442.1
A28: KEYED IN | B28: 0
A29: Promotional Electronic In | B29: 0
A30: Non-cashableElectronic in In | B30: 0
A31: VOUCHER IN | B31: 0
A32: Cashable Voucher in | B32: 0
A33: promotional Voucher in | B33: 0
A34: Non-cashable Voucher in | B34: 0
A36: TOTAL OUT | B36: 3620892
A37: Physical Coin Out | B37: 0
A38: Total Winnings Paid By Attendant | B38: 32962
A39: cancelled credits paid by attentant | B39: 2515.53
A41: VOUCHER OUT | B41: 0
... A44: CASHLESS OUT | B44: 3585414.4
A45: Cashable Electronic Out | B45: =B44 -> 3585414.4
A46: Promotional Electronic Out | B46: 0
A47: Non-cashable Electronic Out | B47: 0
...

Sheet 112
A2: Machine Brand | B2: EGT | C2: A
B3: MEGA VISION
A4: 1 Credit = $ | B4: 1
A6: Machine Number | B6: 112
A7: GAME | B7: MULTI GAMES
A8: TOTAL BET (COIN IN) | B8: 6219054.3
A9: TOTAL CASHABLE PLAYED | B9: =+B8 -> 6219054.3
A10: TOTAL PROMOTIONAL PLAYED | B10: 0
A11: TOTAL NON-CASHABLE PLAYED | B11: 0
A13: TOTAL WON | B13: 5985294.8
A14: TOTAL WINNINGS TO CREDIT | B14: 5908552.3
A15: WINNINGS FROM PAYTABLE (COIN OUT) | B15: =B14 -> 5908552.3
A16: WINNINGS FROM PROGRESSIVES | B16: 0
A17: WINNINGS FROM EXTERNAL BONUSES | B17: 0
A18: TOTAL WINNINGS PAID BY ATTENDANT | B18: 76742.5
A19: Attendant Paid Paytable Winnings | B19: =+B18 -> 76742.5
A20: Attedant Paid Progressives | B20: 0
A21: Attendant Paid External Bonuses | B21: 0
B23: 0
A24: Machine Hold % | B24: 0.0376
A25: Machine Yield % | B25: 0.9624
A26: Weighted average TRTP % | B26: 0.9567
A28: TOTAL IN | B28: 1531588.3
A29: Physical Coin In | B29: 0
A30: Bill In | B30: 851714
A31: Cashless in | B31: 679874.32
A32: Cashable Electronic in | B32: =B31 -> 679874.32
A33: KEYED IN | B33: 0
A34: Promotional Electronic In | B34: 0
A35: Non cashable electronic In | B35: 0
A36: Voucher In | B36: 0
A37: Cashable voucher In | B37: 0
A38: Promotional voucher in | B38: 0
A39: Non-cashable Voucher In | B39: 0
A41: TOTAL OUT | B41: 1297828.8
A42: Physical Coin Out | B42: 0
A43: Total Winnings Paid By Attendant | B43: 76742.5
A44: Cancelled Credits Paid by Attendant | B44: 547.89
A45: VOUCHER OUT | B45: 0
... A48: CASHLESS OUT | B48: 1220538.4
...

Sheet 118
A2: Machine Brand | B2: EGT | C2: A
B3: MEGA VISION
A4: 1 Credit = $ | B4: 1
A6: Machine Number | B6: 118
A7: GAME | B7: MULTI GAMES
A8: TOTAL BET (COIN IN) | B8: 5415068
A9: TOTAL CASHABLE PLAYED | B9: =B8 -> 5415068
A10: TOTAL PROMOTIONAL PLAYED | B10: 0
A11: TOTAL NON-CASHABLE PLAYED | B11: 0
A13: TOTAL WON | B13: 5252998.5
A14: TOTAL WINNINGS TO CREDIT | B14: 5121816.5
A15: WINNINGS FROM PAYTABLE (COIN OUT) | B15: =+B14 -> 5121816.5
A16: WINNINGS FROM PROGRESSIVES | B16: 0
A17: WINNINGS FROM EXTERNAL BONUSES | B17: 0
A18: TOTAL WINNINGS PAID BY ATTENDANT | B18: 131182
A19: Attendant Paid Paytable Winnings | B19: =+B18 -> 131182
A20: Attedant Paid Progressives | B20: 0
A21: Attendant Paid External Bonuses | B21: 0
B23: 0
A24: Machine Hold % | B24: 0.03
A25: Machine Yield % | B25: 0.97
A26: Weighted average TRTP % | B26: 0.9567
A28: TOTAL IN | B28: 1314566.8
A29: Physical Coin In | B29: 0
A30: Bill In | B30: 787854
A31: Cashless in | B31: 526712.81
A32: Cashable Electronic in | B32: =+B31 -> 526712.81
A33: KEYED IN | B33: 0
A34: Promotional Electronic In | B34: 0
A35: Non cashable electronic In | B35: 0
A36: Voucher In | B36: 0
A37: Cashable voucher In | B37: 0
A38: Promotional voucher in | B38: 0
A39: Non-cashable Voucher In | B39: 0
A41: TOTAL OUT | B41: 1152497.3
A42: Physical Coin Out | B42: 0
A43: Total Winnings Paid By Attendant | B43: 131182
A44: Cancelled Credits Paid by Attendant | B44: 1121.48
A45: VOUCHER OUT | B45: 0
... A48: CASHLESS OUT | B48: 1020193.8
...

Sheet 95
I1: AMES WON
A2: Machine Brand | B2: ATRONIC
A4: 1 Credit = $ | B4: 1
A6: Machine Number | B6: 95
A7: GAME | B7: AMAZING AMBER
A8: True In | B8: 206191.71
A9: Pysical Coin In | B9: 0
A10: Bills in | B10: 146458
A11: Total voucher In | B11: 0
A12: Total Cashless Transactions In | B12: 59733.71
A13: Money Wagered | B13: 600383.9
A14: Money Won (incl Bonus Jackpot) | B14: 561183.48
A15: Money Won (incl Bonus JP Bonus) | B15: 563882.44
A16: Money Won (incl Bonus JP Bonus, Jackpot) | B16: =+B15 -> 563882.44
A17: Total Bonus In | B17: 0
A18: True Out | B18: 169690.25
A19: Physical Coin Out | B19: 0
A20: Total voucher Out | B20: 0
A21: Total Cashless Transactions Out | B21: 169686.99
A22: Handpay | B22: 3.26
A23: Handpay (Incl Jackpot) | B23: =B22 -> 3.26 | E23: =+B23-#REF! -> #REF!
A24: Jackpot | B24: 0
A25: Jackpot (Incl Progressive JP, Bonus) | B25: 0
A26: Net Win(Incl Progressive JP) | B26: 36501.46
A27: Net Win (Incl Progressive JP, Bonus) | B27: =B26 -> 36501.46
A28: Total Drop | B28: 146458
A29: Current Payout %(Incl Progressive JP) | B29: 0.9392
A30: Current Payout % (Incl Progressive JP, Bonus) | B30: =+B29 -> 0.9392

Sheet 35
A2: Machine Brand | B2: IGT | C2: A
B3: VIDEO POKER
A4: 1 Credit = $ | B4: 1
B5: ram clear 16/02/2021
A6: Machine Number | B6: 35
A7: GAME | B7: VIDEO POKER
A8: COINS IN | B8: 1562764
A9: PHYSICAL COINS IN | B9: 0
A10: COINS OUT | B10: 1466807
A11: PHYSICAL COINS OUT | B11: 0
A12: CANCELLED CREDITS | B12: 0
A13: JACKPOT | B13: 32000
A14: YEILD | B14: 63957
A15: DROP | B15: 0
A16: TOP WINS | B16: 8
A17: TOTAL WINS | B17: 178647
A18: LOSSES | B18: 225083
A19: GAMES PLAYED | B19: 403730
... A26: RESETS | B26: 48393
B27: 0
A28: CREDIT BET | B28: 1562764
A29: CREDIT WON | B29: 1466807
A30: CREDIT PAID | B30: 0
A31: MECHANICAL METERS
A32: CREDIT IN | B32: 1562764
A33: CREDIT OUT | B33: 1498807
A34: COIN DROP | B34: 0
A35: TOTAL HANDPAYS | B35: 32000
A36: BILL DROP | B36: 0
A37: BONUS METERS
A38: DEDUCTIBLE | B38: 0
A39: NON DEDUCTIBLE | B39: 0
A41: CUMULATIVE EFT DOWNLOADS
A42: PROMOTIONAL CREDITS | B42: 0
A43: CASHABLE CREDITS | B43: 222875
A44: NON CASHABLE CREDITS
A45: CUMULATIVE EFT UPLOADS
A46: UPLOADED CREDITS | B46: 126918
A47: CURRENT EFT METERS
A48: PROMOTIONAL CREDITS | B48: 0
...

Sheet 113
A2: Machine Brand | B2: EGT | C2: A
B3: MEGA VISION
A4: 1 Credit = $ | B4: 1
A6: Machine Number | B6: 113
A7: GAME | B7: MULTI GAMES
A8: TOTAL BET (COIN IN) | B8: 6847121.4
A9: TOTAL CASHABLE PLAYED | B9: =+B8 -> 6847121.4
A10: TOTAL PROMOTIONAL PLAYED | B10: 0
A11: TOTAL NON-CASHABLE PLAYED | B11: 0
A13: TOTAL WON | B13: 6585498.9
A14: TOTAL WINNINGS TO CREDIT | B14: 6481161.4
A15: WINNINGS FROM PAYTABLE (COIN OUT) | B15: =B14 -> 6481161.4
A16: WINNINGS FROM PROGRESSIVES | B16: 0
A17: WINNINGS FROM EXTERNAL BONUSES | B17: 0
A18: TOTAL WINNINGS PAID BY ATTENDANT | B18: 104337.5
A19: Attendant Paid Paytable Winnings | B19: =+B18 -> 104337.5
A20: Attedant Paid Progressives | B20: 0
A21: Attendant Paid External Bonuses | B21: 0
B23: 0
A24: Machine Hold % | B24: 0.0383
A25: Machine Yield % | B25: 0.9617
A26: Weighted average TRTP % | B26: 0.9567
A28: TOTAL IN | B28: 1873805.6
A29: Physical Coin In | B29: 0
A30: Bill In | B30: 977092
A31: Cashless in | B31: 896713.58
A32: Cashable Electronic in | B32: =+B31 -> 896713.58
A33: KEYED IN | B33: 0
A34: Promotional Electronic In | B34: 0
A35: Non cashable electronic In | B35: 0
A36: Voucher In | B36: 0
A37: Cashable voucher In | B37: 0
A38: Promotional voucher in | B38: 0
A39: Non-cashable Voucher In | B39: 0
A41: TOTAL OUT | B41: 1612183.1
A42: Physical Coin Out | B42: 0
A43: Total Winnings Paid By Attendant | B43: 104337.5
A44: Cancelled Credits Paid by Attendant | B44: 1712.54
A45: VOUCHER OUT | B45: 0
... A48: CASHLESS OUT | B48: 1506133.1
...

Sheet 27
A2: Machine Brand | B2: IGT | C2: C
A4: 1 Credit = $ | B4: 0.01
A6: Machine Number | B6: 27
A7: GAME | B7: PHARAOS FORTUNE
A8: COINS IN (total played) | B8: 85000551
B9: 0
A10: total won | B10: 79303306
A11: machine paid won | B11: =B10 -> 79303306
A12: coin out (machine paid paytable) | B12: =B11 -> 79303306
A13: MACHINE PAID PROGRESSIVE PAYOUT | B13: 0
A14: MACH PAID EXTERNAL BONUS PAYOUT | B14: 0
A15: ATTENDANT PAID WON | B15: 0
A16: ATTENDANT PAID JACKPOTS | B16: 0
A17: ATT PAID PROGRESSIVE PAYOUT
A18: ATT PAID EXTERNAL BONUS PAYOUT | B18: 0
A20: JACKPOT RESET TO CREDIT | B20: 0
B21: 0
A22: machine hold % | B22: 0.067
A23: machine yield % | B23: 0.9329
A24: base machine hold % | B24: =B22 -> 0.067
A25: base machine yield % | B25: =B23 -> 0.9329
A27: total in | B27: 22538301
A28: physical coin in | B28: 0
A29: bill in | B29: 14848500
A30: CASHLESS IN | B30: 7689801
A31: EFT IN | B31: 0
A32: WAT IN | B32: 7689801
A33: CASHABLE ELEC PROMO IN | B33: 0
A34: NON CASHABLE ELEC PROMO IN | B34: 0
A35: VOUCHER IN | B35: 0
A36: CASHABLE VOUCHER IN | B36: 0
A37: CASHABLE PROMO VOUCHER IN | B37: 0
A39: COUPON PROMO IN(NONCASHABLE) | B39: 0
N40: ×
A41: COIN DROP | B41: 0
A43: Total Out | B43: 16841056
A44: physical coin out | B44: 0
A45: Cashless out | B45: 16790158
A46: WAT out | B46: =B45 -> 16790158
A47: cashable elctronic promo out | B47: 0
...

Sheet 15
A2: Machine Brand | B2: IGT | C2: B
B3: i game
A4: 1 Credit = $ | B4: =0.02 -> 0.02 | C4: $
A6: Machine Number | B6: 15
A7: GAME | B7: CLEOPATRA
A8: TOTAL PLAYED (COINS IN) | B8: 259140885
A9: TOTAL WON | B9: 246822753
A10: COINS WON (COINS OUT) | B10: 243692193
A11: JACKPOT WON | B11: 3130560
A12: MACHINE HOLD | B12: 0.0472
A13: MACHINE YEILD | B13: 0.9524
A15: TOTAL IN ( CREDIT ) | B15: 74657527
A16: COIN IN
A17: COIN IN 2 | B17: 0
A18: BILL IN | B18: 43701000
A19: DEBIT IN | B19: 30956527
A20: KEYED IN | B20: 0
A21: TOTAL OUT CREDIT | B21: 62339395
A22: COIN OUT
A23: DEBIT OUT | B23: 59208835
A24: JACKPOT HANDPAY | B24: 3130560
A25: CANCELLED CREDIT | B25: 0
A27: TOTAL MONEY TO DROP | B27: 43701000
A28: BILL TO DROP | B28: =B27 -> 43701000
A29: COINS TO DROP | B29: 0
A31: HOPPER FILL | B31: 0
A33: TOTAL GAMES PLAYED | B33: 2182270
A34: TOTAL GAME WON | B34: 770830
A35: TOTAL GAMES LOST | B35: 1411440
A37: PHYSICAL COINS IN | B37: 0
A38: PHYSICAL COINS 2 IN | B38: 0
A39: PHYSICAL COINS OUT | B39: 0
A42: BASE MACHINE HOLD | B42: 0.0475
A43: BASE MACHINE YEILD | B43: 0.9524
A45: System total Bonus won | B45: 0
A46: System deductable bonus won | B46: 0
A47: system non deductable bonus won | B47: 0
A48: system wager match bonus won
A49: system deductible mjt won
A50: system non deductible mjt won
...

Sheet 12
A2: Machine Brand | B2: IGT | C2: B
B3: i game
A4: 1 Credit = $ | B4: =0.02 -> 0.02 | C4: $
B5: 41519
A6: Machine Number | B6: 12
A7: GAME | B7: RISQUE BUSINESS | T7: 2
A8: TOTAL PLAYED (COINS IN) | B8: 62518685
A9: TOTAL WON | B9: 59552569
A10: COINS WON (COINS OUT) | B10: =B9 -> 59552569
A11: JACKPOT WON | B11: 0 | AB11: 150
A12: MACHINE HOLD | B12: 0.0474
A13: MACHINE YEILD | B13: 0.9525
B14: 0
A15: TOTAL IN ( CREDIT ) | B15: 21055799
A16: COIN IN | B16: 0
A17: COIN IN 2 | B17: 0
A18: BILL IN | B18: 12817000
A19: DEBIT IN | B19: 8238799
A20: KEYED IN | B20: 0
A21: TOTAL OUT CREDIT | B21: 18089549
A22: COIN OUT | B22: 9
A23: DEBIT OUT | B23: 18089540
A24: JACKPOT HANDPAY | B24: 0
A25: CANCELLED CREDIT | B25: 0
A27: TOTAL MONEY TO DROP | B27: 12817000
A28: BILL TO DROP | B28: =B27 -> 12817000
A29: COINS TO DROP | B29: 0
A31: HOPPER FILL | B31: 0
A33: TOTAL GAMES PLAYED | B33: 1504423
A34: TOTAL GAME WON | B34: 380147
A35: TOTAL GAMES LOST | B35: 1124276
A37: PHYSICAL COINS IN | B37: 0
A38: PHYSICAL COINS 2 IN | B38: 0
A39: PHYSICAL COINS OUT | B39: 0
A42: BASE MACHINE HOLD | B42: 0.0474
A43: BASE MACHINE YEILD | B43: 0.9525
A45: System total Bonus won | B45: 0
A46: System deductable bonus won | B46: 0
... A50: system non deductible mjt won | B50: 0
A51: Annalyste
...

Sheet 81
A2: Machine Brand | B2: BAUM | C2: A
A4: 1 Credit = $ | B4: 0.01 | G4: 2
A6: Machine Number | B6: 81
A7: GAME | B7: DRACULAS VIII
B8: VALUE (USD) | C8: CREDITS
A9: TOTAL IN | B9: =C9/E9 -> 60 | C9: 6000 | E9: 100
A10: PHYSICAL COINS IN | B10: 0 | C10: 0 | E10: 47170
A11: BILL IN | B11: =C11/E11 -> 60 | C11: =C9 -> 6000 | E11: 100
A12: REMOTE IN | B12: 0 | C12: 0
A13: CASHLESS : IN | B13: 0 | C13: 0
A14: CASHABLE ELECTRONIC IN | B14: 0 | C14: 0
A15: RESTRICTED IN | B15: 0 | C15: 0
A16: NON RESTRICTED PROM. IN | B16: 0 | C16: 0
A17: TICKET & VOUCHER IN | B17: 0 | C17: 0
A18: TOTAL OUT (Total cancelled credits) | B18: =C18/E18 -> 150 | C18: 15000 | E18: 100
A19: PHYSICAL COINS OUT | B19: 0
A20: ATTENDANT PAID CANCELLED CREDITS | B20: =B18 -> 150 | C20: =C18 -> 15000
A21: WINNINGS PAID BY ATTENDANT | B21: 0 | C21: 0
A22: ATTENDANT PAID BONUSES | B22: 0 | C22: 0
A23: CASHLESS : OUT | B23: 0 | C23: 0
A24: CASHABLE ELECTRONIC : OUT | B24: 0 | C24: 0
A25: RESTRICTED : OUT | B25: 0 | C25: 0
A26: NON RESTRICTED PROM. : OUT | B26: 0 | C26: 0
A27: TICKET & VOUCHER OUT | B27: 0 | C27: 0
A28: TOTAL IN - TOTAL OUT : | B28: -90
A29: TOTAL BET (Coin in )
A30: TOTAL WINNING TO CREDITS (Coin out ) | B30: 0 | C30: 16865
A31: GAME WINNING TO CREDITS | C31: 25865
A32: WINNINGS FROM BONUSES | B32: 0 | C32: 25865
A33: MACHINE YIELD (win /bet) | B33: 1.5336
A34: GAMES PLAYED | C34: 417 | E34: 11
B35: COUNT | C35: TOTAL USD | D35: CREDIT
A37: LEGACY EXTERNAL BONUSES | B37: 0 | C37: 0 | D37: 0
A38: LEGACY EXTERNAL DEDUCTIBLE | B38: 0 | C38: 0 | D38: 0
A39: LEGACY EXTERNAL NON-DEDUCTIBLE | B39: 0 | C39: 0 | D39: 0
A40: LEGACY EXTERNAL WAGER M. | B40: 0 | C40: 0 | D40: 0
A41: LEGACY EXTERNEL TO HANDPAY | B41: 0 | C41: 0 | D41: 0
A42: AFT EXTERNAL BONUSES | B42: 0 | C42: 0 | D42: 0
A43: AFT EXTERNAL BONUSES CASHABLE | B43: 0 | C43: 0 | D43: 0
A44: AFT EXTERNAL BONUSES NONRESTRICTED | B44: 0 | C44: 0 | D44: 0
...

Sheet 94
I1: AMES WON
A2: Machine Brand | B2: ATRONIC
A4: 1 Credit = $ | B4: 1
A6: Machine Number | B6: 94
A7: GAME | B7: ABSOLUTE AZURE DELUXE
A8: True In | B8: 50722.81 | C8: 6
A9: Pysical Coin In | B9: 0
A10: Bills in | B10: 25646
A11: Total voucher In | B11: 0
A12: Total Cashless Transactions In | B12: 25076.81
A13: Money Wagered | B13: 147287.92
A14: Money Won (incl Bonus Jackpot) | B14: 139870.43
A15: Money Won (incl Bonus JP Bonus) | B15: 173570.98
A16: Money Won (incl Bonus JP Bonus, Jackpot) | B16: =+B15 -> 173570.98
A17: Total Bonus In | B17: 0
A18: True Out | B18: 43305.32
A19: Physical Coin Out | B19: 0
A20: Total voucher Out | B20: 0
A21: Total Cashless Transactions Out | B21: 43305.32
A22: Handpay | B22: 0
A23: Handpay (Incl Jackpot) | B23: 0
A24: Jackpot | B24: 0
A25: Jackpot (Incl Progressive JP, Bonus) | B25: 0
A26: Net Win(Incl Progressive JP) | B26: 7417.49
A27: Net Win (Incl Progressive JP, Bonus) | B27: =B26 -> 7417.49
A28: Total Drop | B28: 25646
A29: Current Payout %(Incl Progressive JP) | B29: 0.9496
A30: Current Payout % (Incl Progressive JP, Bonus) | B30: =B29 -> 0.9496

Sheet 42
A2: Machine Brand | B2: EGT | C2: A
B3: MEGA VISION
A4: 1 Credit = $ | B4: 1
A6: Machine Number | B6: 42
A7: GAME | B7: MULTI GAMES
A8: TOTAL BET (COIN IN) | B8: 19838935
A9: TOTAL CASHABLE PLAYED | B9: =B8 -> 19838935
A10: TOTAL PROMOTIONALPLAYED | B10: 0
A11: TOTAL NONCASHABLE PLAYED | B11: 0
A13: TOTAL WON | B13: 18973932
A14: TOTAL WINNINGS TO CREDIT | B14: 18880081
A15: WINNINGS PAYTABLE(COIN OUT) | B15: =B14 -> 18880081
A16: WINNINGS FROM PROGRESSIVES | B16: 0
A17: WINNINGS FROM EXTERNAL BONUSES | B17: 0
A18: TOTAL WINNINGS PAID BY ATTENDANT | B18: 93850.5
A19: TOTAL WINNINGS PAID BY ATTENDANT | B19: =B18 -> 93850.5
A20: Attedant Paid Progressives | B20: 0
A21: Attendant Paid External Bonuses | B21: 0
A24: TOTAL IN | B24: 5199062.5
A25: Physical Coin In | B25: 0
A26: Bill In | B26: 3713170
A27: Cashless in | B27: 1485892.6
A28: Cashable Electronic in | B28: =B27 -> 1485892.6
A29: KEYED IN | B29: 0
A30: Promotional Electronic In | B30: 0
A31: Non cashable electronic In | B31: 0
A32: Voucher In | B32: 0
A33: Cashable voucher In | B33: 0
A34: Promotional voucher in | B34: 0
A35: Non-cashable Voucher In | B35: 0
A37: TOTAL OUT | B37: 4334058.8
A38: Physical Coin Out | B38: 0
A39: Total Winnings Paid By Attendant | B39: 93850.5
A40: Cancelled Credits Paid by Attendant | B40: 4241.86
A41: VOUCHER OUT | B41: 0
... A44: CASHLESS OUT | B44: 4235966.4
A45: Cashable Electronic Out | B45: =B44 -> 4235966.4
A46: Promotional Electronic Out | B46: 0
A47: Non-cashable Electronic Out | B47: 0
A49: TOTAL CANCELLED CREDITS | B49: 4240208.3
...

Sheet 93
I1: AMES WON
A2: Machine Brand | B2: ATRONIC
A4: 1 Credit = $ | B4: 1
A6: Machine Number | B6: 93
A7: GAME | B7: GAMBLING GREEN DELUXE | E7: 6666
A8: True In | B8: 24746.77
A9: Pysical Coin In | B9: 0
A10: Bills in | B10: 16373
A11: Total voucher In | B11: 0
A12: Total Cashless Transactions In | B12: 8373.77
A13: Money Wagered | B13: 85250.14
A14: Money Won (incl Bonus Jackpot) | B14: 79315.01
A15: Money Won (incl Bonus JP Bonus) | B15: 79475.54
A16: Money Won (incl Bonus JP Bonus, Jackpot) | B16: =+B15 -> 79475.54
A17: Total Bonus In | B17: 0
A18: True Out | B18: 18943.38
A19: Physical Coin Out | B19: 0
A20: Total voucher Out | B20: 0
A21: Total Cashless Transactions Out | B21: 18972.17
A22: Handpay | B22: 0
A23: Handpay (Incl Jackpot) | B23: 0
A24: Jackpot | B24: 0
A25: Jackpot (Incl Progressive JP, Bonus) | B25: 0
A26: Net Win(Incl Progressive JP) | B26: 5774.6
A27: Net Win (Incl Progressive JP, Bonus) | B27: =B26 -> 5774.6
A28: Total Drop | B28: 16373
A29: Current Payout %(Incl Progressive JP) | B29: 0.9222
A30: Current Payout % (Incl Progressive JP, Bonus) | B30: =B29 -> 0.9222

Sheet 82
A2: Machine Brand | B2: BAUM | C2: A
A4: 1 Credit = $ | B4: 0.01 | G4: 2
A6: Machine Number | B6: 82
A7: GAME | B7: DRACULAS VII
B8: 0 | C8: CREDITS
A9: TOTAL IN | B9: =C9/E9 -> 617 | C9: 61700 | E9: 100
A10: PHYSICAL COINS IN | B10: 0 | C10: 0
A11: BILL IN | B11: =C11/E11 -> 617 | C11: =C9 -> 61700 | E11: 100
A12: REMOTE IN | B12: 0 | C12: 0
A13: CASHLESS : IN | B13: 0 | C13: 0
A14: CASHABLE ELECTRONIC IN | B14: 0 | C14: 0
A15: RESTRICTED IN | B15: 0 | C15: 0
A16: NON RESTRICTED PROM. IN | B16: 0 | C16: 0
A17: TICKET & VOUCHER IN | B17: 0 | C17: 0
A18: TOTAL OUT (Total cancelled credits) | B18: =C18/E18 -> 270.1 | C18: 27010 | E18: 100
A19: PHYSICAL COINS OUT | B19: 0 | C19: 0
A20: ATTENDANT PAID CANCELLED CREDITS | B20: =B18 -> 270.1 | C20: =C18 -> 27010
A21: WINNINGS PAID BY ATTENDANT | B21: 0 | C21: 0
A22: ATTENDANT PAID BONUSES | B22: 0 | C22: 0
A23: CASHLESS : OUT | B23: 0 | C23: 0
A24: CASHABLE ELECTRONIC : OUT | B24: 0 | C24: 0
A25: RESTRICTED : OUT | B25: 0 | C25: 0
A26: NON RESTRICTED PROM. : OUT | B26: 0 | C26: 0
A27: TICKET & VOUCHER OUT | C27: 0
A28: TOTAL IN - TOTAL OUT : | B28: 346.9
A29: TOTAL BET (Coin in ) | C29: 186760
A30: TOTAL WINNING TO CREDITS (Coin out ) | B30: 0 | C30: 152070
A31: GAME WINNING TO CREDITS | B31: 0 | C31: 152070
A32: WINNINGS FROM BONUSES | B32: 0 | C32: =C30-C31 -> 0
A33: MACHINE YIELD (win /bet) | B33: 0.8142
A34: GAMES PLAYED | C34: 1666
B35: COUNT | C35: TOTAL USD | D35: CREDIT
A37: LEGACY EXTERNAL BONUSES | B37: 0 | C37: 0 | D37: 0
A38: LEGACY EXTERNAL DEDUCTIBLE | B38: 0 | C38: 0 | D38: 0
A39: LEGACY EXTERNAL NON-DEDUCTIBLE | B39: 0 | C39: 0 | D39: 0
A40: LEGACY EXTERNAL WAGER M. | B40: 0 | C40: 0 | D40: 0
A41: LEGACY EXTERNEL TO HANDPAY | B41: 0 | C41: 0 | D41: 0
A42: AFT EXTERNAL BONUSES | B42: 0 | C42: 0 | D42: 0
A43: AFT EXTERNAL BONUSES CASHABLE | B43: 0 | C43: 0 | D43: 0
A44: AFT EXTERNAL BONUSES NONRESTRICTED | B44: 0 | C44: 0 | D44: 0
...

Sheet 61N
J1: AMES WON
A2: Machine Brand | B2: ATRONIC | C2: A
B3: KING KONG
A4: 1 Credit = $ | B4: 1
B5: ram cleared started play 11/08/2021
A6: Machine Number | B6: 61N
A7: GAME | B7: EAGLE PEAKS
A8: Money Wagered | B8: 729.21
A9: Mon,won+prog+Bonus,wo JP; | B9: 881.2
A10: Mon,won+prog+Bonus,w JP; | B10: =B9 -> 881.2
A11: Total Drop | B11: 0
A12: Coin Drop | B12: 0
A13: Hand paid wo JP | B13: 0
A14: Hand paid w JP | B14: 0
A15: Games played | B15: 1129
A16: Games Won | B16: 365
A17: Jackpots Wo prog.and Bonus | B17: 0
A18: Jackpots W prog.and Bonus | B18: 0
A19: Jackpot Hits | B19: 0
A20: Door Opens | B20: 470
A21: Pysical Coin In | B21: 0
A22: Pysical Coin Out | B22: 0
A23: True In | B23: 800.73 | C23: =B23-B41 -> 800.73 | F23: =+B23-B41 -> 800.73
A24: True Out | B24: 952.72
A25: Net Win | B25: -151.99
A26: Cur.payout% with Bonus | B26: 1.2084
A27: Cur.payout% w/o Bonus | B27: =B26 -> 1.2084
A28: Coins Overpaid | B28: 0
A29: Games/Door | B29: 0
A30: Games/Power | B30: 0
A31: Hopper Drawer | B31: 0
A32: Logic Door | B32: 14
A33: Drop Door | B33: 0
A34: Billbox Door | B34: 16
A35: Bill and Drop Door | B35: =B34 -> 16
A36: Billacceptor Stacker | B36: 0
A37: Double Utilisation % | B37: 0
A38: Double Up Wagered | B38: 0
A39: Double Up Won | B39: 0
A40: Double Up Payout % | B40: 0
...

Sheet 60N
J1: AMES WON
A2: Machine Brand | B2: ATRONIC | C2: A
B3: KING KONG
A4: 1 Credit = $ | B4: 1
B5: ram cleared started play 23/02/2023
A6: Machine Number | B6: 60N
A7: GAME | B7: Desert Dancer
A8: Money Wagered | B8: 1016.33
A9: Mon,won+prog+Bonus,wo JP; | B9: 988.17
A10: Mon,won+prog+Bonus,w JP; | B10: =B9 -> 988.17
A11: Total Drop | B11: 0
A12: Coin Drop | B12: 0
A13: Hand paid wo JP | B13: 0
A14: Hand paid w JP | B14: 0
A15: Games played | B15: 3533
A16: Games Won | B16: 978
A17: Jackpots Wo prog.and Bonus | B17: 0
A18: Jackpots W prog.and Bonus | B18: 0
A19: Jackpot Hits | B19: 0
A20: Door Opens | B20: 980
A21: Pysical Coin In | B21: 0
A22: Pysical Coin Out | B22: 0
A23: True In | B23: 904.48 | C23: =B23-B41 -> 904.48 | F23: =+B23-B41 -> 904.48
A24: True Out | B24: 876.32
A25: Net Win | B25: 28.16
A26: Cur.payout% with Bonus | B26: 0.9722
A27: Cur.payout% w/o Bonus | B27: =B26 -> 0.9722
A28: Coins Overpaid | B28: 0
A29: Games/Door | B29: 0
A30: Games/Power | B30: 52
A31: Hopper Drawer | B31: 11
A32: Logic Door | B32: 5
A33: Drop Door | B33: 0
A34: Billbox Door | B34: 34
A35: Bill and Drop Door | B35: 34
A36: Billacceptor Stacker | B36: 3
A37: Double Utilisation % | B37: 0
A38: Double Up Wagered | B38: 0
A39: Double Up Won | B39: 0
... A42: Total Bills Count | B42: 0
...

Sheet 55N
J1: AMES WON
A2: Machine Brand | B2: ATRONIC | C2: A
B3: KING KONG
A4: 1 Credit = $ | B4: 1
B5: ram cleared started play 11/08/2021
A6: Machine Number | B6: 55N
A7: GAME | B7: PRINCESS OF THE AMAZON
A8: Money Wagered | B8: 254
A9: Mon,won+prog+Bonus,wo JP; | B9: 142.4
A10: Mon,won+prog+Bonus,w JP; | B10: =B9 -> 142.4
A11: Total Drop | B11: =+B10 -> 142.4
A12: Coin Drop | B12: 0
A13: Hand paid wo JP | B13: 0
A14: Hand paid w JP | B14: 0
A15: Games played | B15: 957
A16: Games Won | B16: 244
A17: Jackpots Wo prog.and Bonus | B17: 0
A18: Jackpots W prog.and Bonus | B18: 0
A19: Jackpot Hits | B19: 0
A20: Door Opens | B20: 461
A21: Pysical Coin In | B21: 0
A22: Pysical Coin Out | B22: 0
A23: True In | B23: 413.58 | C23: =B23-B41 -> 413.58 | F23: =+B23-B41 -> 413.58
A24: True Out | B24: 302.02
A25: Net Win | B25: 111.6
A26: Cur.payout% with Bonus | B26: 0.5606
A27: Cur.payout% w/o Bonus | B27: =B26 -> 0.5606
A28: Coins Overpaid | B28: 0
A29: Games/Door | B29: 0
A30: Games/Power | B30: 0
A31: Hopper Drawer | B31: 0
A32: Logic Door | B32: 7
A33: Drop Door | B33: 0
A34: Billbox Door | B34: 207
A35: Bill and Drop Door | B35: 87
A36: Billacceptor Stacker | B36: 294
A37: Double Utilisation % | B37: 0
A38: Double Up Wagered | B38: 0
A39: Double Up Won | B39: 0
... A42: Total Bills Count | B42: 0
...

Sheet 57
J1: AMES WON
A2: Machine Brand | B2: ATRONIC | C2: A
A4: 1 Credit = $ | B4: 1
B5: ram clear 03/11/2020
A6: Machine Number | B6: 57
A7: GAME | B7: FIRE CHIEF
A8: Money Wagered | B8: 1079.78
A9: Mon,won+prog+Bonus,wo JP; | B9: 1008.05
A10: Mon,won+prog+Bonus,w JP; | B10: =B9 -> 1008.05
A11: Total Drop | B11: 0
A12: Coin Drop | B12: 0
A13: Hand paid wo JP | B13: 0
A14: Hand paid w JP | B14: 0
A15: Games played | B15: 1709
A16: Games Won | B16: 512
A17: Jackpots Wo prog.and Bonus | B17: 0
A18: Jackpots W prog.and Bonus | B18: 0
A19: Jackpot Hits | B19: 0
A20: Door Opens | B20: 579
A21: Pysical Coin In | B21: 0
A22: Pysical Coin Out | B22: 0
A23: True In | B23: 1481.57 | C23: =B23-B41 -> 1481.57 | F23: =+B23-B41 -> 1481.57
A24: True Out | B24: 1409.84
A25: Net Win | B25: 71.73
A26: Cur.payout% with Bonus | B26: 0.9335
A27: Cur.payout% w/o Bonus | B27: =B26 -> 0.9335
A28: Coins Overpaid | B28: 0
A29: Games/Door | B29: 0
A30: Games/Power | B30: 0
A31: Hopper Drawer | B31: 0
A32: Logic Door | B32: 2
A33: Drop Door | B33: 1
A34: Billbox Door | B34: 66
A35: Bill and Drop Door | B35: 67
A36: Billacceptor Stacker | B36: 2
A37: Double Utilisation % | B37: 0
A38: Double Up Wagered | B38: 0
A39: Double Up Won | B39: 0
... A42: Total Bills Count | B42: 0

Sheet 58
J1: AMES WON
A2: Machine Brand | B2: ATRONIC | C2: A
A4: 1 Credit = $ | B4: 1
A6: Machine Number | B6: 58
A7: GAME | B7: 1421 VOYAGES OF ZHENGHE
A8: Money Wagered | B8: 8426.18
A9: Mon,won+Bonus,w JP; | B9: 7826.14
A10: Mon,won+prog+Bonus,wo JP; | B10: =B9 -> 7826.14
A11: Mon,won+prog+Bonus,w JP; | B11: =B10 -> 7826.14
A12: Total Drop | B12: 0
A13: Coin Drop | B13: 0
A14: Hand paid wo JP | B14: 0
A15: Hand paid w JP | B15: 0
A16: Games played | B16: 2531
A17: Games Won | B17: 686
A18: Jackpots Wo prog.and Bonus | B18: 0
A19: Jackpots W prog.and Bonus | B19: 0
A20: Jackpot Hits | B20: 0
A21: Door Opens | B21: 556
A22: Pysical Coin In | B22: 0
A23: Pysical Coin Out | B23: 0 | D23: 3
A24: True In | B24: 3139.21 | C24: =B24-B42 -> 3139.21 | F24: =+B24-B42 -> 3139.21
A25: True Out | B25: 2539.17
A26: Net Win | B26: 600.04
A27: Cur.payout% with Bonus | B27: 0.9287
A28: Cur.payout% w/o Bonus | B28: =B27 -> 0.9287
A29: Coins Overpaid | B29: 0
A30: Games/Door | B30: 0
A31: Games/Power | B31: 0
A32: Hopper Drawer | B32: 1
A33: Logic Door | B33: 8
A34: Drop Door | B34: 0
A35: Billbox Door | B35: 1
A36: Bill and Drop Door | B36: =B35 -> 1
A37: Billacceptor Stacker | B37: 11
A38: Double Utilisation % | B38: 0
A39: Double Up Wagered | B39: 0
A40: Double Up Won | B40: 0
A41: Double Up Payout % | B41: 0
A42: Total Bills Currency | B42: =B12 -> 0
...

Sheet 59
J1: AMES WON
A2: Machine Brand | B2: ATRONIC | C2: A
A4: 1 Credit = $ | B4: 1
A6: Machine Number | B6: 59
A7: GAME | B7: ROYAL KEY
A8: Money Wagered | B8: 3424.44
A9: Mon,won+Bonus,w JP; | B9: 2920.62
A10: Mon,won+prog+Bonus,wo JP; | B10: =+B9 -> 2920.62
A11: Mon,won+prog+Bonus,w JP; | B11: =+B9 -> 2920.62
A12: Total Drop | B12: 0
A13: Coin Drop | B13: 0
A14: Hand paid wo JP | B14: 0
A15: Hand paid w JP | B15: 0
A16: Games played | B16: 5271
A17: Games Won | B17: 1703
A18: Jackpots Wo prog.and Bonus | B18: 0
A19: Jackpots W prog.and Bonus | B19: 0
A20: Jackpot Hits | B20: 0
A21: Door Opens | B21: 608
A22: Pysical Coin In | B22: 0
A23: Pysical Coin Out | B23: 0
A24: True In | B24: 3204.92 | C24: =B24-B42 -> 3204.92 | F24: =+B24-B42 -> 3204.92
A25: True Out | B25: 2701.1
A26: Net Win | B26: 503.82
A27: Cur.payout% with Bonus | B27: 0.8528
A28: Cur.payout% w/o Bonus | B28: =B27 -> 0.8528
A29: Coins Overpaid | B29: 0
A30: Games/Door | B30: 0
A31: Games/Power | B31: 152
A32: Hopper Drawer | B32: 0
A33: Logic Door | B33: 2
A34: Drop Door | B34: 0
A35: Billbox Door | B35: 0
A36: Bill and Drop Door | B36: 0
A37: Billacceptor Stacker | B37: 9
A38: Double Utilisation % | B38: 0
A39: Double Up Wagered | B39: 0
A40: Double Up Won | B40: 0
A41: Double Up Payout % | B41: 0
A42: Total Bills Currency | B42: =B12 -> 0
...

Sheet 48N
J1: AMES WON
A2: Machine Brand | B2: ATRONIC | C2: A
B3: KING KONG
A4: 1 Credit = $ | B4: 1
B5: ram cleared started play 11/08/2021
A6: Machine Number | B6: 48
A7: GAME | B7: PRINCESS OF THE AMAZON
A8: Money Wagered | B8: 3248.62
A9: Mon,won+prog+Bonus,wo JP; | B9: 2914.63
A10: Mon,won+prog+Bonus,w JP; | B10: =B9 -> 2914.63
A11: Total Drop | B11: 286
A12: Coin Drop | B12: 0
A13: Hand paid wo JP | B13: 0
A14: Hand paid w JP | B14: 0
A15: Games played | B15: 21849
A16: Games Won | B16: 4901
A17: Jackpots Wo prog.and Bonus | B17: 0
A18: Jackpots W prog.and Bonus | B18: 0
A19: Jackpot Hits | B19: 39
A20: Door Opens | B20: 220
A21: Pysical Coin In | B21: 0
A22: Pysical Coin Out | B22: 0
A23: True In | B23: 2300.14 | C23: =B23-B41 -> 2014.14 | F23: =+B23-B41 -> 2014.14
A24: True Out | B24: 1966.15
A25: Net Win | B25: 541.29
A26: Cur.payout% with Bonus | B26: 0.8333
A27: Cur.payout% w/o Bonus | B27: =B26 -> 0.8333
A28: Coins Overpaid | B28: 0
A29: Games/Door | B29: 0
A30: Games/Power | B30: 2795
A31: Hopper Drawer | B31: 0
A32: Logic Door | B32: 14
A33: Drop Door | B33: 0
A34: Billbox Door | B34: 0
A35: Bill and Drop Door | B35: =B34 -> 0
A36: Billacceptor Stacker | B36: 84
A37: Double Utilisation % | B37: 0
A38: Double Up Wagered | B38: 0
A39: Double Up Won | B39: 0
A40: Double Up Payout % | B40: 0
...

Sheet 50N
J1: AMES WON
A2: Machine Brand | B2: ATRONIC | C2: A
B3: KING KONG
A4: 1 Credit = $ | B4: 1
A6: Machine Number | B6: 50
A7: GAME | B7: PRINCESS OF THE AMAZON
A8: Money Wagered | B8: 64312.98
A9: Mon,won+prog+Bonus,wo JP; | B9: 62353.25 | E9: 13359
A10: Mon,won+prog+Bonus,w JP; | B10: 62353.25
A11: Total Drop | B11: 19031
A12: Coin Drop | B12: 0
A13: Hand paid wo JP | B13: 0
A14: Hand paid w JP | B14: 0
A15: Games played | B15: 87021
A16: Games Won | B16: 22453
A17: Jackpots Wo prog.and Bonus | B17: 0
A18: Jackpots W prog.and Bonus | B18: 0
A19: Jackpot Hits | B19: 201 | F19: 985
A20: Door Opens | B20: 1022
A21: Pysical Coin In | B21: 0
A22: Pysical Coin Out | B22: 0
A23: True In | B23: 51812.64 | C23: =B23-B41 -> 32781.64 | F23: =+B23-B41 -> 32781.64
A24: True Out | B24: 49852.91
A25: Net Win | B25: 7332.51
A26: Cur.payout% with Bonus | B26: 0.8859
A27: Cur.payout% w/o Bonus | B27: =B26 -> 0.8859
A28: Coins Overpaid | B28: 0
A29: Games/Door | B29: 0
A30: Games/Power | B30: 5933
A31: Hopper Drawer | B31: 0
A32: Logic Door | B32: 31
A33: Drop Door | B33: 0
A34: Billbox Door | B34: 472
A35: Bill and Drop Door | B35: =B34 -> 472
A36: Billacceptor Stacker | B36: 282
A37: Double Utilisation % | B37: 0
A38: Double Up Wagered | B38: 0
A39: Double Up Won | B39: 0
A40: Double Up Payout % | B40: 0
A41: Total Bills Currency | B41: 19031
...

Sheet 49N
J1: AMES WON
A2: Machine Brand | B2: ATRONIC | C2: A
B3: KING KONG
A4: 1 Credit = $ | B4: 1
A6: Machine Number | B6: 49
A7: GAME | B7: PRINCESS OF THE AMAZON
A8: Money Wagered | B8: 91267.12
A9: Mon,won+prog+Bonus,wo JP; | B9: 74861.17 | E9: 13359
A10: Mon,won+prog+Bonus,w JP; | B10: 86195.64
A11: Total Drop | B11: 35339
A12: Coin Drop | B12: 0
A13: Hand paid wo JP | B13: 0
A14: Hand paid w JP | B14: 0
A15: Games played | B15: 195039
A16: Games Won | B16: 48783
A17: Jackpots Wo prog.and Bonus | B17: 0
A18: Jackpots W prog.and Bonus | B18: 0
A19: Jackpot Hits | B19: 434 | F19: 985
A20: Door Opens | B20: 2215
A21: Pysical Coin In | B21: 0
A22: Pysical Coin Out | B22: 0
A23: True In | B23: 62113.88 | C23: =B23-B41 -> 26774.88 | F23: =+B23-B41 -> 26774.88
A24: True Out | B24: 57042.4
A25: Net Win | B25: 16405.95
A26: Cur.payout% with Bonus | B26: 0.8202
A27: Cur.payout% w/o Bonus | B27: =B26 -> 0.8202
A28: Coins Overpaid | B28: 0
A29: Games/Door | B29: 0
A30: Games/Power | B30: 6765
A31: Hopper Drawer | B31: 0
A32: Logic Door | B32: 41
A33: Drop Door | B33: 0
A34: Billbox Door | B34: 707
A35: Bill and Drop Door | B35: =B34 -> 707
A36: Billacceptor Stacker | B36: 656
A37: Double Utilisation % | B37: 0
A38: Double Up Wagered | B38: 0
A39: Double Up Won | B39: 0
A40: Double Up Payout % | B40: 0
A41: Total Bills Currency | B41: 35339
...

Sheet 103
J1: AMES WON
A2: Machine Brand | B2: ATRONIC | C2: A
B3: KING KONG
A4: 1 Credit = $ | B4: 1
B5: ram cleared started play 11/08/2021
A6: Machine Number | B6: 103
A7: GAME | B7: PRINCESS OF THE AMAZON
A8: Money Wagered | B8: 15326.74
A9: Mon,won+prog+Bonus,wo JP; | B9: 13279.5
A10: Mon,won+prog+Bonus,w JP; | B10: 13279.5
A11: Total Drop | B11: 5111
A12: Coin Drop | B12: 0
A13: Hand paid wo JP | B13: 0
A14: Hand paid w JP | B14: 0
A15: Games played | B15: 28628
A16: Games Won | B16: 8263
A17: Jackpots Wo prog.and Bonus | B17: 0
A18: Jackpots W prog.and Bonus | B18: 0
A19: Jackpot Hits | B19: 67
... A22: Pysical Coin Out | B22: 0
A23: True In | B23: 9354.67 | C23: =B23-B41 -> 4243.67 | F23: =+B23-B41 -> 4243.67
A24: True Out | B24: 7307.43
A25: Net Win | B25: 3272.9
A26: Cur.payout% with Bonus | B26: 78.64
A27: Cur.payout% w/o Bonus | B27: 78.64
A28: Coins Overpaid | B28: 0
A29: Games/Door | B29: 0
A30: Games/Power | B30: 286
A31: Hopper Drawer | B31: 0
A32: Logic Door | B32: 17
A33: Drop Door | B33: 0
A34: Billbox Door | B34: 213
A35: Bill and Drop Door | B35: =B34 -> 213
A36: Billacceptor Stacker | B36: 172
A37: Double Utilisation % | B37: 0
A38: Double Up Wagered | B38: 0
A39: Double Up Won | B39: 0
A40: Double Up Payout % | B40: 0
A41: Total Bills Currency | B41: 5111
A42: Total Bills Count | B42: 184
...

Sheet 102
J1: AMES WON
A2: Machine Brand | B2: ATRONIC | C2: A
B3: KING KONG
A4: 1 Credit = $ | B4: 1
B5: ram cleared started play 11/08/2021
A6: Machine Number | B6: 102
A7: GAME | B7: PRINCESS OF THE AMAZON
A8: Money Wagered | B8: 262883.34
A9: Mon,won+prog+Bonus,wo JP; | B9: 241402.82
A10: Mon,won+prog+Bonus,w JP; | B10: 249557.36
A11: Total Drop | B11: 51660
A12: Coin Drop | B12: 0
A13: Hand paid wo JP | B13: 0
A14: Hand paid w JP | B14: 8154.54
A15: Games played | B15: 242545
A16: Games Won | B16: 62445
A17: Jackpots Wo prog.and Bonus | B17: 80.54
A18: Jackpots W prog.and Bonus | B18: 8154.54
A19: Jackpot Hits | B19: 602
... A22: Pysical Coin Out | B22: 0
A23: True In | B23: 103367.12 | C23: =B23-B41 -> 51707.12 | F23: =+B23-B41 -> 51707.12
A24: True Out | B24: 90041.14
A25: Net Win | B25: 45973.82
A26: Cur.payout% with Bonus | B26: 82.51
A27: Cur.payout% w/o Bonus | B27: =B26 -> 82.51
A28: Coins Overpaid | B28: 0
A29: Games/Door | B29: 0
A30: Games/Power | B30: 480
A31: Hopper Drawer | B31: 0
A32: Logic Door | B32: 220
A33: Drop Door | B33: 0
A34: Billbox Door | B34: 12
A35: Bill and Drop Door | B35: 12
A36: Billacceptor Stacker | B36: 539
A37: Double Utilisation % | B37: 0
A38: Double Up Wagered | B38: 1.16
A39: Double Up Won | B39: 0.4
... A42: Total Bills Count | B42: 1467

Sheet 101
J1: AMES WON
A2: Machine Brand | B2: ATRONIC | C2: A
B3: KING KONG
A4: 1 Credit = $ | B4: 1
B5: ram cleared started play 11/08/2021
A6: Machine Number | B6: 101
A7: GAME | B7: PRINCESS OF THE AMAZON
A8: Money Wagered | B8: 120157.84
A9: Mon,won+prog+Bonus,wo JP; | B9: 111148.9
A10: Mon,won+prog+Bonus,w JP; | B10: 121344.36
A11: Total Drop | B11: 29577
A12: Coin Drop | B12: 0
A13: Hand paid wo JP | B13: 0
A14: Hand paid w JP | B14: 10195.46
A15: Games played | B15: 86050
A16: Games Won | B16: 26370
A17: Jackpots Wo prog.and Bonus | B17: 92.4
A18: Jackpots W prog.and Bonus | B18: 10195.46
A19: Jackpot Hits | B19: 245
... A22: Pysical Coin Out | B22: 0
A23: True In | B23: 51684 | C23: =B23-B41 -> 22107 | F23: =+B23-B41 -> 22107
A24: True Out | B24: 52870.52
A25: Net Win | B25: 21332.68
A26: Cur.payout% with Bonus | B26: 0.8224
A27: Cur.payout% w/o Bonus | B27: =B26 -> 0.8224
A28: Coins Overpaid | B28: 0
A29: Games/Door | B29: 0
A30: Games/Power | B30: 402
A31: Hopper Drawer | B31: 0
A32: Logic Door | B32: 7
A33: Drop Door | B33: 0
A34: Billbox Door | B34: 56
A35: Bill and Drop Door | B35: =B34 -> 56
A36: Billacceptor Stacker | B36: 312
A37: Double Utilisation % | B37: 0
A38: Double Up Wagered | B38: 0
A39: Double Up Won | B39: 0
A40: Double Up Payout % | B40: 0
A41: Total Bills Currency | B41: 29577
A42: Total Bills Count | B42: 726
...

Sheet 18N
A2: Machine Brand | B2: IGT | C2: C
A4: 1 Credit = $ | B4: 0.01
A6: Machine Number | B6: 18
A7: GAME | B7: PHARAOS FORTUNE
A8: COINS IN (total played) | B8: 574309
A10: total won | B10: 532921
A11: machine paid won | B11: 452571
A12: coin out (machine paid paytable) | B12: 0
A13: MACHINE PAID PROGRESSIVE PAYOUT | B13: 0
A14: MACH PAID EXTERNAL BONUS PAYOUT | B14: 0
A15: ATTENDANT PAID WON | B15: 0
A16: ATTENDANT PAID JACKPOTS | B16: 0
A17: ATT PAID PROGRESSIVE PAYOUT
A18: ATT PAID EXTERNAL BONUS PAYOUT | B18: 0
A20: JACKPOT RESET TO CREDIT | B20: 0
B21: 0
A22: machine hold % | B22: 0.072
A23: machine yield % | B23: 0.9279
A24: base machine hold % | B24: =B22 -> 0.072
A25: base machine yield % | B25: =B23 -> 0.9279
A27: total in | B27: 531005
A28: physical coin in | B28: 0
A29: bill in | B29: 283750
A30: CASHLESS IN | B30: 247255
A31: EFT IN | B31: 0
A32: WAT IN | B32: 0
A33: CASHABLE ELEC PROMO IN | B33: 0
A34: NON CASHABLE ELEC PROMO IN | B34: 0
A35: VOUCHER IN | B35: 0
A36: CASHABLE VOUCHER IN | B36: 0
A37: CASHABLE PROMO VOUCHER IN | B37: 0
A39: COUPON PROMO IN(NONCASHABLE) | B39: 0
N40: ×
A41: COIN DROP | B41: 0
A43: Total Out | B43: 489617
A44: physical coin out | B44: 0
A45: Debit out | B45: 409267
A46: Debit out | B46: 80350
A47: jackpot handpay | B47: 80350
A48: voucher out | B48: 0
...

Sheet 26N 
A2: Machine Brand | B2: IGT | C2: B
B3: i game
A4: 1 Credit = $ | B4: =0.02 -> 0.02 | C4: $
A6: Machine Number | B6: 26
A7: GAME | B7: FORTUNE COOKIE
A8: TOTAL PLAYED (COINS IN) | B8: 1418908
A9: TOTAL WON | B9: 1245127
A10: COINS WON (COINS OUT) | B10: =B9 -> 1245127
A11: JACKPOT WON | B11: 0
A12: MACHINE HOLD | B12: 0.1224
A13: MACHINE YEILD | B13: 0.8775
A15: TOTAL IN ( CREDIT ) | B15: 578742
A16: COIN IN | B16: 0
A17: COIN IN 2 | B17: 0
A18: BILL IN | B18: 263000
A19: DEBIT IN | B19: 315742
A20: KEYED IN | B20: 0
A21: cash voucher IN | B21: 0
A22: TOTAL OUT CREDIT | B22: 403455
A23: COIN OUT | B23: 0
... A27: CANCELLED CREDIT | B27: 0
A29: TOTAL MONEY TO DROP | B29: =B18 -> 263000
A30: BILL TO DROP | B30: =B29 -> 263000
A31: COINS TO DROP | B31: 0
A33: HOPPER FILL | B33: 0
A35: TOTAL GAMES PLAYED | B35: 22938
A36: TOTAL GAME WON | B36: 10765
A37: TOTAL GAMES LOST | B37: 12173
A39: PHYSICAL COINS IN | B39: 0
A40: PHYSICAL COINS 2 IN | B40: 0
A41: PHYSICAL COINS OUT | B41: 0
A44: BASE MACHINE HOLD | B44: =B12 -> 0.1224
A45: BASE MACHINE YEILD | B45: =B13 -> 0.8775
A47: Lecture compteurs
A49: Nom_______________
A51: Sign_______________
A53: Annalyste
A55: Nom_____________
A57: Sign_______________

Sheet 34
A2: Machine Brand | B2: IGT | C2: A
B3: VIDEO POKER
A4: 1 Credit = $ | B4: 1
A6: Machine Number | B6: 34
A7: GAME | B7: VIDEO POKER
A8: COINS IN | B8: 2277533
A9: PHYSICAL COINS IN | B9: 0
A10: COINS OUT | B10: 2146068
A11: PHYSICAL COINS OUT | B11: 0
A12: CANCELLED CREDITS | B12: 324
A13: JACKPOT | B13: 64000
A14: YEILD | B14: 67465
A15: DROP | B15: 0
A16: TOP WINS | B16: 16
A17: TOTAL WINS | B17: 235064
A18: LOSSES | B18: 295572
A19: GAMES PLAYED | B19: 530636
... A26: RESETS | B26: 3810
B27: 0
A28: CREDIT BET | B28: 2277533
A29: CREDIT WON | B29: 2146067
A30: CREDIT PAID | B30: 324
A31: MECHANICAL METERS | B31: 0
A32: CREDIT IN | B32: =B28 -> 2277533
A33: CREDIT OUT | B33: 2210067
A34: COIN DROP | B34: 0
A35: TOTAL HANDPAYS | B35: 64324
A36: BILL DROP | B36: 0
A37: BONUS METERS
A38: DEDUCTIBLE | B38: 0
A39: NON DEDUCTIBLE | B39: 0
A41: CUMULATIVE EFT DOWNLOADS
A42: PROMOTIONAL CREDITS | B42: 0
A43: CASHABLE CREDITS | B43: 458712
A44: NON CASHABLE CREDITS | B44: 0
A45: CUMULATIVE EFT UPLOADS
A46: UPLOADED CREDITS | B46: 326923
A47: CURRENT EFT METERS | B47: 0
A48: PROMOTIONAL CREDITS | B48: 0
A49: BUFFERED CREDITS | B49: 0
...

Sheet 28
A2: Machine Brand | B2: IGT | C2: B
B3: i game
A4: 1 Credit = $ | B4: =0.02 -> 0.02 | C4: $
A6: Machine Number | B6: 28
A7: GAME | B7: FORTUNE COOKIE
A8: TOTAL PLAYED (COINS IN) | B8: 18345801
A9: TOTAL WON | B9: 17448191
A10: COINS WON (COINS OUT) | B10: 17368013
A11: JACKPOT WON | B11: 80178
A12: MACHINE HOLD | B12: 0.0489
A13: MACHINE YEILD | B13: 0.951
A15: TOTAL IN ( CREDIT ) | B15: 7448670
A16: COIN IN | B16: 0
A17: COIN IN 2 | B17: 0
A18: BILL IN | B18: 3958300
A19: DEBIT IN | B19: 3490370
A20: KEYED IN | B20: 0
... A22: TOTAL OUT CREDIT | B22: 6541396
A23: COIN OUT
A24: CASH VOUCHER OUT
A25: DEBIT OUT | B25: 6377433
A26: JACKPOT HANDPAY | B26: 80178
A27: CANCELLED CREDIT | B27: 83785
A29: TOTAL MONEY TO DROP | B29: 3958300
A30: BILL TO DROP | B30: =B29 -> 3958300
A31: COINS TO DROP | B31: 0
A33: HOPPER FILL | B33: 0
A35: TOTAL GAMES PLAYED | B35: 623970
A36: TOTAL GAME WON | B36: 234973
A37: TOTAL GAMES LOST | B37: 388997
A39: PHYSICAL COINS IN | B39: 0
A40: PHYSICAL COINS 2 IN | B40: 0
A41: PHYSICAL COINS OUT | B41: 0
A44: BASE MACHINE HOLD | B44: =B12 -> 0.0489
A45: BASE MACHINE YEILD | B45: =B13 -> 0.951
A47: Lecture compteurs
A49: Nom_______________
A51: Sign_______________
A53: Annalyste
A55: Nom_____________
...

Sheet 13N
A2: Machine Brand | B2: IGT | C2: B
B3: i game
A4: 1 Credit = $ | B4: =0.02 -> 0.02 | C4: $
A6: Machine Number | B6: 13
A7: GAME | B7: FORTUNE COOKIE
A8: TOTAL PLAYED (COINS IN) | B8: 231711
A9: TOTAL WON | B9: 227976
A10: COINS WON (COINS OUT) | B10: =B9 -> 227976
A11: JACKPOT WON | B11: 0
A12: MACHINE HOLD | B12: 0.0161
A13: MACHINE YEILD | B13: 0.9838
A15: TOTAL IN ( CREDIT ) | B15: 114125
A16: COIN IN | B16: 0
A17: COIN IN 2 | B17: 0
A18: BILL IN | B18: 52750
A19: DEBIT IN | B19: 61375
A20: KEYED IN | B20: 0
A21: cash voucher IN | B21: 0
A22: TOTAL OUT CREDIT | B22: 110390
A23: COIN OUT | B23: 0
A24: CASH VOUCHER OUT
A25: DEBIT OUT | B25: =B22 -> 110390
A26: JACKPOT HANDPAY | B26: 0
A27: CANCELLED CREDIT | B27: 0
A29: TOTAL MONEY TO DROP | B29: 52750
A30: BILL TO DROP | B30: =B29 -> 52750
A31: COINS TO DROP | B31: 0
A33: HOPPER FILL | B33: 0
A35: TOTAL GAMES PLAYED | B35: 2174
A36: TOTAL GAME WON | B36: 880
A37: TOTAL GAMES LOST | B37: 1294
A39: PHYSICAL COINS IN | B39: 0
A40: PHYSICAL COINS 2 IN | B40: 0
A41: PHYSICAL COINS OUT | B41: 0
A44: BASE MACHINE HOLD | B44: 0.0161
A45: BASE MACHINE YEILD | B45: 0.9838
A47: Lecture compteurs
A49: Nom_______________
A51: Sign_______________
A53: Annalyste
...

Sheet 16N
A2: Machine Brand | B2: IGT | C2: B
B3: i game
A4: 1 Credit = $ | B4: =0.02 -> 0.02 | C4: $
A6: Machine Number | B6: 16
A7: GAME | B7: FORTUNE COOKIE
A8: TOTAL PLAYED (COINS IN) | B8: 3499758
A9: TOTAL WON | B9: 3336618
A10: COINS WON (COINS OUT) | B10: 3197868
A11: JACKPOT WON | B11: 138750
A12: MACHINE HOLD | B12: 0.0466
A13: MACHINE YEILD | B13: 0.9533
A15: TOTAL IN ( CREDIT ) | B15: 2621278
A16: COIN IN | B16: 0
A17: COIN IN 2 | B17: 0
A18: BILL IN | B18: 348750
A19: DEBIT IN | B19: 2272528
A20: KEYED IN | B20: 0
... A23: COIN OUT | B23: 0
A24: CASH VOUCHER OUT
A25: DEBIT OUT | B25: 2319388
A26: JACKPOT HANDPAY | B26: 138750
A27: CANCELLED CREDIT | B27: 0
A29: TOTAL MONEY TO DROP | B29: =B18 -> 348750
A30: BILL TO DROP | B30: =B29 -> 348750
A31: COINS TO DROP | B31: 0
A33: HOPPER FILL | B33: 0
A35: TOTAL GAMES PLAYED | B35: 29051
A36: TOTAL GAME WON | B36: 14631
A37: TOTAL GAMES LOST | B37: 14420
A39: PHYSICAL COINS IN | B39: 0
A40: PHYSICAL COINS 2 IN | B40: 0
A41: PHYSICAL COINS OUT | B41: 0
A44: BASE MACHINE HOLD | B44: =B12 -> 0.0466
A45: BASE MACHINE YEILD | B45: =B13 -> 0.9533
A47: Lecture compteurs
A49: Nom_______________
A51: Sign_______________
A53: Annalyste
A55: Nom_____________
A57: Sign_______________

Sheet 44
A2: Machine Brand | C2: A
B3: hot space 3
A4: 1 Credit = $ | B4: 1
A6: Machine Number | B6: 44
A7: GAME | B7: MULTI GAMES
A8: BET | B8: 2330166.9
A9: WIN | B9: 2149819.7
A10: GAMES PLAYED | B10: 3228120
A11: AVERAGE BET | B11: 0.72
A12: GAMES WON | B12: 416561
A13: GAMES LOST | B13: 2811559
A14: FREE GAMES | B14: 104920
A15: GAMBLE GAMES | B15: 1097
A16: PAY OUT PERCENTAGE | B16: 0.9226
A17: HOLD | B17: 0.0774
A18: SLOT DOOR OPENS | B18: 6712
A19: POWER RESET | B19: 3216
... A26: CASH IN | B26: 807524.11
A27: BILL IN | B27: =B26 -> 807524.11
A28: COIN IN | B28: 0
G29: 0

Sheet 45
A2: Machine Brand | B2: EGT | C2: A
B3: HOT SPACE3
A4: 1 Credit = $ | B4: 1
A6: Machine Number | B6: 45
A7: GAME | B7: MULTI GAMES | G7: 5
A8: BET | B8: 1457485.7
A9: WIN | B9: 1345860.5
A10: GAMES PLAYED | B10: 1943466 | M10: 4
A11: AVERAGE BET | B11: 0.75
A12: GAMES WON | B12: 369308
A13: GAMES LOST | B13: 1574158
A14: FREE GAMES | B14: 112977
A15: GAMBLE GAMES | B15: 1619
A16: PAY OUT PERCENTAGE | B16: 0.9234
A17: HOLD | B17: 0.0766
A18: SLOT DOOR OPENS | B18: 7421
A19: POWER RESET | B19: 4195
A20: OUT | B20: 10371 | E20: IN
A21: IN | B21: 465680 | E21: =B21=B24+B26 -> TRUE
A22: OUT/IN | B22: 0.7603
A23: IN-OUT | B23: 111625.22
A24: KEY IN | B24: 10371
A25: KEY OFF | B25: 354054.78
A26: BILL IN | B26: 455309
A27: CASH IN | B27: =B26 -> 455309

Sheet 83
A2: Machine Brand | B2: BAUM | C2: A
A4: 1 Credit = $ | B4: 0.01 | G4: 2
A6: Machine Number | B6: 83
A7: GAME | B7: DRACULAS VII
B8: 0 | C8: CREDITS
A9: TOTAL IN | B9: =C9/E9 -> 870 | C9: 87000 | E9: 100
A10: PHYSICAL COINS IN | B10: 0 | C10: 0
A11: BILL IN | B11: =C11/E11 -> 870 | C11: =C9 -> 87000 | E11: 100
A12: REMOTE IN | B12: 0 | C12: 0
A13: CASHLESS : IN | B13: 0 | C13: 0
A14: CASHABLE ELECTRONIC IN | B14: 0 | C14: 0
A15: RESTRICTED IN | B15: 0 | C15: 0
A16: NON RESTRICTED PROM. IN | B16: 0 | C16: 0
A17: TICKET & VOUCHER IN | B17: 0 | C17: 0
A18: TOTAL OUT (Total cancelled credits) | B18: =C18/E18 -> 540 | C18: 54000 | E18: 100
A19: PHYSICAL COINS OUT | B19: 0 | C19: 0
A20: ATTENDANT PAID CANCELLED CREDITS | B20: =B18 -> 540 | C20: =+C18 -> 54000
A21: WINNINGS PAID BY ATTENDANT | B21: 0 | C21: 0
A22: ATTENDANT PAID BONUSES | B22: 0 | C22: 0
A23: CASHLESS : OUT | B23: 0 | C23: 0
A24: CASHABLE ELECTRONIC : OUT | B24: 0 | C24: 0
A25: RESTRICTED : OUT | B25: 0 | C25: 0
A26: NON RESTRICTED PROM. : OUT | B26: 0 | C26: 0
A27: TICKET & VOUCHER OUT | C27: 0
A28: TOTAL IN - TOTAL OUT : | B28: 330
A29: TOTAL BET (Coin in ) | C29: 282155
A30: TOTAL WINNING TO CREDITS (Coin out ) | B30: 0 | C30: 249155
A31: GAME WINNING TO CREDITS | B31: 0 | C31: =C30 -> 249155
A32: WINNINGS FROM BONUSES | B32: 0 | C32: 0
A33: MACHINE YIELD (win /bet) | B33: 0.883
A34: GAMES PLAYED | B34: 0 | C34: 4814
B35: COUNT | C35: TOTAL USD | D35: CREDIT
A37: LEGACY EXTERNAL BONUSES | B37: 0 | C37: 0 | D37: 0
A38: LEGACY EXTERNAL DEDUCTIBLE | B38: 0 | C38: 0 | D38: 0
A39: LEGACY EXTERNAL NON-DEDUCTIBLE | B39: 0 | C39: 0 | D39: 0
A40: LEGACY EXTERNAL WAGER M. | B40: 0 | C40: 0 | D40: 0
A41: LEGACY EXTERNEL TO HANDPAY | B41: 0 | C41: 0 | D41: 0
A42: AFT EXTERNAL BONUSES | B42: 0 | C42: 0 | D42: 0
A43: AFT EXTERNAL BONUSES CASHABLE | B43: 0 | C43: 0 | D43: 0
A44: AFT EXTERNAL BONUSES NONRESTRICTED | B44: 0 | C44: 0 | D44: 0
...

Sheet 47
J1: AMES WON
A2: Machine Brand | B2: EGT | C2: A
B3: MEGA VISION
A4: 1 Credit = $ | B4: 1
A6: Machine Number | B6: 47
A7: GAME | B7: MULTI GAMES
A8: BET | B8: 2429959.9
A9: WIN | B9: 2243640.2
A10: GAMES PLAYED | B10: 4222182
A11: AVERAGE BET | B11: 0.58
A12: GAMES WON | B12: 588593
A13: GAMES LOST | B13: 3633589
A14: FREE GAMES | B14: 58275
A15: GAMBLE GAMES | B15: 894
A16: PAY OUT PERCENTAGE | B16: 0.9233
A17: HOLD | B17: 0.0767
A18: SLOT DOOR OPENS | B18: 6084
A19: POWER RESET | B19: 3181
A20: OUT | B20: 613981.31 | K20: 22
A21: IN | B21: 800301
A22: OUT/IN | B22: 0.7672
A23: IN-OUT | B23: 186319.69
A24: KEY IN | B24: 18796 | J24: 22
A25: KEY OFF | B25: 613981.31
A26: CASH IN | B26: 781505
A27: BILL in | B27: =B26 -> 781505
A28: COIN IN | B28: 0

Sheet 78
A2: Machine Brand | B2: BAUM | C2: A
A4: 1 Credit = $ | B4: 0.01 | G4: 2
A6: Machine Number | B6: 78
A7: GAME | B7: DRACULAS VI
B8: VALUE (USD) | C8: CREDITS
A9: TOTAL IN | B9: =+C9/E9 -> 300 | C9: 30000 | E9: 100
A10: PHYSICAL COINS IN | B10: 0 | C10: 0
A11: BILL IN | B11: =C11/E11 -> 300 | C11: =C9 -> 30000 | E11: 100
A12: REMOTE IN | B12: 0 | C12: 0
A13: CASHLESS : IN | B13: 0 | C13: 0 | D13: 44
A14: CASHABLE ELECTRONIC IN | B14: 0 | C14: 0
A15: RESTRICTED IN | B15: 0 | C15: 0
A16: NON RESTRICTED PROM. IN | B16: 0 | C16: 0
A17: TICKET & VOUCHER IN | B17: 0 | C17: 0
A18: TOTAL OUT (Total cancelled credits) | B18: 0 | C18: 0 | E18: 100
A19: PHYSICAL COINS OUT | B19: 0 | C19: 0
A20: ATTENDANT PAID CANCELLED CREDITS | B20: =B18 -> 0 | C20: 0
A21: WINNINGS PAID BY ATTENDANT | B21: 0 | C21: 0
A22: ATTENDANT PAID BONUSES | B22: 0 | C22: 0
